<?xml version="1.0"?>
<robot xmlns:xacro="http://wiki.ros.org/xacro">

    <xacro:macro name="default_inertial" params="mass">
        <inertial>
            <mass value="${mass}" />
            <inertia ixx="1.0" ixy="0.0" ixz="0.0"
                iyy="1.0" iyz="0.0"
                izz="1.0" />
        </inertial>
    </xacro:macro>

  <xacro:include filename="$(find kuka_resources)/urdf/common_materials.xacro"/>

  <!-- <xacro:include filename="$(find kuka_description)/urdf/kuka.transmission.xacro" /> -->
  <!-- <xacro:include filename="$(find kuka_description)/urdf/kuka.gazebo.xacro" /> -->
<!-- 
  <xacro:macro name="kuka_kr4r600" params="prefix transmission_hw_interface:=hardware_interface/EffortJointInterface"> -->
  <xacro:include filename="$(find kuka_resources)/urdf/common_constants.xacro"/>
  <xacro:macro name="kuka_kr4r600" params="prefix">
    <link name="${prefix}base_link">
    <xacro:default_inertial mass="1"/>
      <visual>
        <origin xyz="0 0 0" rpy="0 0 0" />
        <geometry>
          <mesh filename="package://kuka_kr4_support/meshes/kr4r600/visual/base_link.stl" />
        </geometry>
        <xacro:material_kuka_pedestal />
      </visual>

      <collision>
        <origin xyz="0 0 0" rpy="0 0 0" />
        <geometry>
          <mesh filename="package://kuka_kr4_support/meshes/kr4r600/collision/base_link.stl" />
        </geometry>
      </collision>
<!-- 
      <inertial>
        <origin xyz="0 0 0" rpy="0 0 0"/>
        <mass value="7"/>
        <inertia
            ixx="30160574464.000000" ixy="268355824.000000" ixz="396794944.000000"
            iyy="49449443328.00000" iyz="74363816.000000"
            izz="47570612224.000000"/>
      </inertial> -->

    </link>

    <link name="${prefix}link_1">
    <xacro:default_inertial mass="1"/>
      <visual>
        <origin xyz="0 0 0" rpy="0 0 0" />
        <geometry>
          <mesh filename="package://kuka_kr4_support/meshes/kr4r600/visual/link_1.stl" />
        </geometry>
        <xacro:material_kuka_ral_pure_white />
      </visual>

      <collision>
        <origin xyz="0 0 0" rpy="0 0 0" />
        <geometry>
          <mesh filename="package://kuka_kr4_support/meshes/kr4r600/collision/link_1.stl" />
        </geometry>
      </collision>
<!-- 
      <inertial>
        <origin xyz="0 0 0" rpy="0 0 0"/>
        <mass value="5"/>
        <inertia
          ixx="29069639680.000000" ixy="16955148.000000" ixz="-75115704.000000"
          iyy="18764271616.000000" iyz="180538688.000000"
          izz="20780234752.000000"/>
      </inertial> -->

    </link>

    <link name="${prefix}link_2">
    <xacro:default_inertial mass="1"/>
      <visual>
        <origin xyz="0 0 0" rpy="0 0 0" />
        <geometry>
          <mesh filename="package://kuka_kr4_support/meshes/kr4r600/visual/link_2.stl" />
        </geometry>
        <xacro:material_kuka_ral_pure_white />
      </visual>

      <collision>
        <origin xyz="0 0 0" rpy="0 0 0" />
        <geometry>
          <mesh filename="package://kuka_kr4_support/meshes/kr4r600/collision/link_2.stl" />
        </geometry>
      </collision>
<!-- 
      <inertial>
        <origin xyz="0 0 0" rpy="0 0 0"/>
        <mass value="6"/>
        <inertia
          ixx="17074209792.000000" ixy="568627456.000000" ixz="-1012415616.000000"
          iyy="54759739392.000000" iyz="2741744.250000"
          izz="62598627328.000000"/>
      </inertial>
 -->
    </link>

    <link name="${prefix}link_3">
    <xacro:default_inertial mass="1"/>
      <visual>
        <origin xyz="0 0 0" rpy="0 0 0" />
        <geometry>
          <mesh filename="package://kuka_kr4_support/meshes/kr4r600/visual/link_3.stl" />
        </geometry>
        <xacro:material_kuka_ral_pure_white />
      </visual>

      <collision>
        <origin xyz="0 0 0" rpy="0 0 0" />
        <geometry>
          <mesh filename="package://kuka_kr4_support/meshes/kr4r600/collision/link_3.stl" />
        </geometry>
      </collision>
<!-- 
      <inertial>
        <origin xyz="0 0 0" rpy="0 0 0"/>
        <mass value="4"/>
        <inertia
          ixx="3538344960.000000" ixy="91869584.000000" ixz="-1087638528.000000"
          iyy="10409157632.000000" iyz="13806910.000000"
          izz="10024766464.000000"/>
      </inertial> -->

    </link>

    <link name="${prefix}link_4">
    <xacro:default_inertial mass="1"/>
      <visual>
        <origin xyz="0 0 0" rpy="0 0 0" />
        <geometry>
          <mesh filename="package://kuka_kr4_support/meshes/kr4r600/visual/link_4.stl" />
        </geometry>
        <xacro:material_kuka_ral_pure_white />
      </visual>

      <collision>
        <origin xyz="0 0 0" rpy="0 0 0" />
        <geometry>
          <mesh filename="package://kuka_kr4_support/meshes/kr4r600/collision/link_4.stl" />
        </geometry>
      </collision>
<!-- 
      <inertial>
        <origin xyz="0 0 0" rpy="0 0 0"/>
        <mass value="3"/>
        <inertia
          ixx="2312632576.000000" ixy="-262303920.000000" ixz="26849928.000000"
          iyy="2560956160.000000" iyz="-46212612.000000"
          izz="3653170944.000000"/>
      </inertial> -->

    </link>

    <link name="${prefix}link_5">
    <xacro:default_inertial mass="1"/>
      <visual>
        <origin xyz="0 0 0" rpy="0 0 0" />
        <geometry>
          <mesh filename="package://kuka_kr4_support/meshes/kr4r600/visual/link_5.stl" />
        </geometry>
        <xacro:material_kuka_ral_pure_white />
      </visual>

      <collision>
        <origin xyz="0 0 0" rpy="0 0 0" />
        <geometry>
          <mesh filename="package://kuka_kr4_support/meshes/kr4r600/collision/link_5.stl" />
        </geometry>
      </collision>
<!-- 
      <inertial>
        <origin xyz="0 0 0" rpy="0 0 0"/>
        <mass value="1.5"/>
        <inertia
          ixx="474922912.000000" ixy="-5465426.000000" ixz="-131389.812500"
          iyy=" 642145344.000000" iyz="98441.296875"
          izz="684424448.000000"/>
      </inertial> -->

    </link>

    <link name="${prefix}link_6">
    <xacro:default_inertial mass="1"/>
      <visual>
        <origin xyz="0 0 0" rpy="0 0 0" />
        <geometry>
          <mesh filename="package://kuka_kr4_support/meshes/kr4r600/visual/link_6.stl" />
        </geometry>
        <xacro:material_kuka_pedestal />
      </visual>

      <collision>
        <origin xyz="0 0 0" rpy="0 0 0" />
        <geometry>
          <mesh filename="package://kuka_kr4_support/meshes/kr4r600/collision/link_6.stl" />
        </geometry>
      </collision>
<!-- 
      <inertial>
        <origin xyz="0 0 0" rpy="0 0 0"/>
        <mass value="0.5"/>
        <inertia
          ixx="9503564.000000" ixy="-344.500275" ixz="2999.466064"
          iyy=" 6104710.000000" iyz="2659.174805"
          izz="6102781.000000"/>
      </inertial> -->

    </link>

    <!-- This frame corresponds to the $FLANGE coordinate system in KUKA KRC controllers. -->
    <link name="${prefix}tool0"/>



    <joint name="${prefix}joint_a1" type="revolute">
      <origin xyz="0 0 0.33" rpy="0 0 0"/>
      <parent link="${prefix}base_link"/>
      <child link="${prefix}link_1"/>
      <axis xyz="0 0 -1"/>
      <limit lower="${-DEG2RAD * 170}" upper="${DEG2RAD * 170}" effort="100" velocity="${DEG2RAD* 530}"/>
    </joint>

    <joint name="${prefix}joint_a2" type="revolute">
      <origin xyz="0 0 0" rpy="0 0 0"/>
      <parent link="${prefix}link_1"/>
      <child link="${prefix}link_2"/>
      <axis xyz="0 1 0"/>
      <limit lower="${-DEG2RAD * 195}" upper="${DEG2RAD * 40}" effort="100" velocity="${DEG2RAD *529}"/>
    </joint>

    <joint name="${prefix}joint_a3" type="revolute">
      <origin xyz="0.290 0 0" rpy="0 0 0"/>
      <parent link="${prefix}link_2"/>
      <child link="${prefix}link_3"/>
      <axis xyz="0 1 0"/>
      <limit lower="${-DEG2RAD * 115}" upper="${DEG2RAD * 150}" effort="100" velocity="${DEG2RAD * 538}"/>
    </joint>

    <joint name="${prefix}joint_a4" type="revolute">
      <origin xyz="0.310 0 0.020" rpy="0 0 0"/>
      <parent link="${prefix}link_3"/>
      <child link="${prefix}link_4"/>
      <axis xyz="-1 0 0"/>
      <limit lower="${-DEG2RAD * 185}" upper="${DEG2RAD * 185}" effort="100" velocity="${DEG2RAD * 600}"/>
    </joint>

    <joint name="${prefix}joint_a5" type="revolute">
      <origin xyz="0 0 0" rpy="0 0 0"/>
      <parent link="${prefix}link_4"/>
      <child link="${prefix}link_5"/>
      <axis xyz="0 1 0"/>
      <limit lower="${-DEG2RAD * 120}" upper="${DEG2RAD * 120}" effort="100" velocity="${DEG2RAD * 600}"/>
    </joint>

    <joint name="${prefix}joint_a6" type="revolute">
      <origin xyz="0.075 0 0" rpy="0 0 0"/>
      <parent link="${prefix}link_5"/>
      <child link="${prefix}link_6"/>
      <axis xyz="-1 0 0"/>
      <limit lower="${-DEG2RAD * 350}" upper="${DEG2RAD* 350}" effort="100" velocity="${DEG2RAD* 800}"/>
    </joint>

    <joint name="${prefix}joint_a6-tool0" type="fixed">
      <parent link="${prefix}link_6"/>
      <child link="${prefix}tool0"/>
      <origin xyz="0 0 0" rpy="0 ${DEG2RAD * 90} 0"/>
    </joint>


<!--   <xacro:kuka_arm_transmission prefix="${prefix}" hw_interface="${transmission_hw_interface}" />
  <xacro:kuka_arm_gazebo prefix="${prefix}" />

 -->
    <!-- ROS base_link to KUKA $ROBROOT coordinate system transform -->
    <link name="${prefix}base" />
    <joint name="${prefix}base_link-base" type="fixed">
      <origin xyz="0 0 0" rpy="0 0 0"/>
      <parent link="${prefix}base_link"/>
      <child link="${prefix}base"/>
    </joint>
  </xacro:macro>

</robot>
